Workbook

Sheet Mapa_RET
A1: CONDIÇÃO | B1: COD_RET | C1: Rec. Efetivo | D1: ACUMULADORES | E1: NCMs_VINCULADOS
A2: 3% de recolhimento efetivo nas operações de vendas internas e interestaduais, destinadas a contribuinte do imposto; | B2: B1 | C2: 0.03 | D2: 5077, 5078, 5079, 5080, 5083 | E2: 33049100, 33049990, 33051000, 33059000, 34011190, 34013000, 33062000, 33072090, 38089199, 38089429, 56012110, 56012190, 96190000
A3: 6% de recolhimento efetivo nas vendas internas destinadas a pessoa jurídica não contribuinte do imposto, quando sujeitas a alíquota igual ou superior a 18% | B3: B2 | C3: 0.06 | E3: 33049100, 33049990, 33051000, 33059000, 34011190, 34013000, 33062000, 33072090, 38089199, 38089429, 56012110, 56012190, 96190000
A4: 1,5% do valor da base de cálculo nas operações interestaduais sujeitas à alíquota de 4% (destinadas a PJ, contribuinte ou não do imposto) | B4: C1 | C4: 0.015 | D4: 8054 | E4: 33049100, 33049990, 33051000, 33059000, 34011190, 34013000, 33062000, 33072090, 38089199, 38089429, 56012110, 56012190, 96190000 | J4: 33049100
J5: 33049990
J6: 33051000
J7: 33059000
J8: 34011190
J9: 34013000
J10: 33062000
J11: 33072090
J12: 38089199
J13: 38089429
J14: 56012110
J15: 56012190
J16: 96190000

Sheet Entradas_AC
A2: Código | B2: Descrição | C2: Vlr Contábil | D2: Base ICMS | E2: Vlr ICMS | F2: Isentas ICMS | G2: Outras ICMS | H2: Vlr IPI | I2: BC ICMS ST | J2: Vlr ICMS ST | K2: Estorno | L2: Observação | M2: Check | N2: ESTORNO DEV
A3: 102 | B3: MERCADORIA P REVENDA | C3: =SUMIF(INDIRECT("TabelaEntradas[AC]"),EntradasAC[[#This Row],[Código]],INDIRECT("TabelaEntradas[VC]")) -> #REF! | D3: =SUMIF(INDIRECT("TabelaEntradas[AC]"),EntradasAC[[#This Row],[Código]],INDIRECT("TabelaEntradas[VC]")) -> #REF! | E3: =SUMIF(INDIRECT("TabelaEntradas[AC]"),EntradasAC[[#This Row],[Código]],INDIRECT("TabelaEntradas[VLR-ICMS]")) -> #REF! | H3: =SUMIF(INDIRECT("TabelaEntradas[AC]"),EntradasAC[[#This Row],[Código]],INDIRECT("TabelaEntradas[VLR_IPI]")) -> #REF! | I3: =SUMIF(INDIRECT("TabelaEntradas[AC]"),EntradasAC[[#This Row],[Código]],INDIRECT("TabelaEntradas[BC-ICMS-ST]")) -> #REF! | J3: =SUMIF(INDIRECT("TabelaEntradas[AC]"),EntradasAC[[#This Row],[Código]],INDIRECT("TabelaEntradas[ICMS-ST]")) -> #REF! | K3: =EntradasAC[[#This Row],[Vlr ICMS]] -> #REF! | M3: SEM FORMULA (FORA DO RET) | N3: =EntradasAC[[#This Row],[Vlr ICMS]]-EntradasAC[[#This Row],[Estorno ]] -> #REF!
A4: 120 | B4: DEVOLUÇÃO VENDA | C4: =SUMIF(INDIRECT("TabelaEntradas[AC]"),EntradasAC[[#This Row],[Código]],INDIRECT("TabelaEntradas[VC]")) -> #REF! | D4: =SUMIF(INDIRECT("TabelaEntradas[AC]"),EntradasAC[[#This Row],[Código]],INDIRECT("TabelaEntradas[VC]")) -> #REF! | E4: =SUMIF(INDIRECT("TabelaEntradas[AC]"),EntradasAC[[#This Row],[Código]],INDIRECT("TabelaEntradas[VLR-ICMS]")) -> #REF! | H4: =SUMIF(INDIRECT("TabelaEntradas[AC]"),EntradasAC[[#This Row],[Código]],INDIRECT("TabelaEntradas[VLR_IPI]")) -> #REF! | I4: =SUMIF(INDIRECT("TabelaEntradas[AC]"),EntradasAC[[#This Row],[Código]],INDIRECT("TabelaEntradas[BC-ICMS-ST]")) -> #REF! | J4: =SUMIF(INDIRECT("TabelaEntradas[AC]"),EntradasAC[[#This Row],[Código]],INDIRECT("TabelaEntradas[ICMS-ST]")) -> #REF! | K4: =EntradasAC[[#This Row],[Vlr ICMS]] -> #REF! | M4: SEM FORMULA (FORA DO RET) | N4: =EntradasAC[[#This Row],[Vlr ICMS]]-EntradasAC[[#This Row],[Estorno ]] -> #REF!
A5: 60 | B5: NF COMPLEMENTAR DO ICMS | C5: =SUMIF(INDIRECT("TabelaEntradas[AC]"),EntradasAC[[#This Row],[Código]],INDIRECT("TabelaEntradas[VC]")) -> #REF! | D5: =SUMIF(INDIRECT("TabelaEntradas[AC]"),EntradasAC[[#This Row],[Código]],INDIRECT("TabelaEntradas[VC]")) -> #REF! | E5: =SUMIF(INDIRECT("TabelaEntradas[AC]"),EntradasAC[[#This Row],[Código]],INDIRECT("TabelaEntradas[VLR-ICMS]")) -> #REF! | H5: =SUMIF(INDIRECT("TabelaEntradas[AC]"),EntradasAC[[#This Row],[Código]],INDIRECT("TabelaEntradas[VLR_IPI]")) -> #REF! | I5: =SUMIF(INDIRECT("TabelaEntradas[AC]"),EntradasAC[[#This Row],[Código]],INDIRECT("TabelaEntradas[BC-ICMS-ST]")) -> #REF! | J5: =SUMIF(INDIRECT("TabelaEntradas[AC]"),EntradasAC[[#This Row],[Código]],INDIRECT("TabelaEntradas[ICMS-ST]")) -> #REF! | K5: =EntradasAC[[#This Row],[Vlr ICMS]] -> #REF! | M5: SEM FORMULA (FORA DO RET) | N5: =EntradasAC[[#This Row],[Vlr ICMS]]-EntradasAC[[#This Row],[Estorno ]] -> #REF!
A6: 133 | B6: FRETE S/ VENDAS | K6: =EntradasAC[[#This Row],[Vlr ICMS]] -> 0 | M6: ESTORNA TUDO | N6: =EntradasAC[[#This Row],[Vlr ICMS]]-EntradasAC[[#This Row],[Estorno ]] -> 0
A7: 233 | B7: FRETE S/ VENDAS (FORA) | K7: =EntradasAC[[#This Row],[Vlr ICMS]] -> 0 | M7: ESTORNA TUDO | N7: =EntradasAC[[#This Row],[Vlr ICMS]]-EntradasAC[[#This Row],[Estorno ]] -> 0
A8: 132 | B8: FRETE S/ VENDAS | K8: =EntradasAC[[#This Row],[Vlr ICMS]] -> 0 | M8: SEM FORMULA (FORA DO RET) | N8: =EntradasAC[[#This Row],[Vlr ICMS]]-EntradasAC[[#This Row],[Estorno ]] -> 0
A9: 171 | B9: IMPORTAÇÃO P/ INDUSTRIALIZAÇÃO | C9: =SUMIF(INDIRECT("TabelaEntradas[AC]"),EntradasAC[[#This Row],[Código]],INDIRECT("TabelaEntradas[VC]")) -> #REF! | D9: =SUMIF(INDIRECT("TabelaEntradas[AC]"),EntradasAC[[#This Row],[Código]],INDIRECT("TabelaEntradas[VC]")) -> #REF! | E9: =SUMIF(INDIRECT("TabelaEntradas[AC]"),EntradasAC[[#This Row],[Código]],INDIRECT("TabelaEntradas[VLR-ICMS]")) -> #REF! | H9: =SUMIF(INDIRECT("TabelaEntradas[AC]"),EntradasAC[[#This Row],[Código]],INDIRECT("TabelaEntradas[VLR_IPI]")) -> #REF! | I9: =SUMIF(INDIRECT("TabelaEntradas[AC]"),EntradasAC[[#This Row],[Código]],INDIRECT("TabelaEntradas[BC-ICMS-ST]")) -> #REF! | J9: =SUMIF(INDIRECT("TabelaEntradas[AC]"),EntradasAC[[#This Row],[Código]],INDIRECT("TabelaEntradas[ICMS-ST]")) -> #REF! | K9: =EntradasAC[[#This Row],[Vlr ICMS]] -> #REF! | M9: SEM FORMULA (FORA DO RET) | N9: =EntradasAC[[#This Row],[Vlr ICMS]]-EntradasAC[[#This Row],[Estorno ]] -> #REF!
A10: 172 | B10: IMPORTAÇÃO P/ COMERCIALIZAÇÃO | C10: =SUMIF(INDIRECT("TabelaEntradas[AC]"),EntradasAC[[#This Row],[Código]],INDIRECT("TabelaEntradas[VC]")) -> #REF! | D10: =SUMIF(INDIRECT("TabelaEntradas[AC]"),EntradasAC[[#This Row],[Código]],INDIRECT("TabelaEntradas[VC]")) -> #REF! | E10: =SUMIF(INDIRECT("TabelaEntradas[AC]"),EntradasAC[[#This Row],[Código]],INDIRECT("TabelaEntradas[VLR-ICMS]")) -> #REF! | H10: =SUMIF(INDIRECT("TabelaEntradas[AC]"),EntradasAC[[#This Row],[Código]],INDIRECT("TabelaEntradas[VLR_IPI]")) -> #REF! | I10: =SUMIF(INDIRECT("TabelaEntradas[AC]"),EntradasAC[[#This Row],[Código]],INDIRECT("TabelaEntradas[BC-ICMS-ST]")) -> #REF! | J10: =SUMIF(INDIRECT("TabelaEntradas[AC]"),EntradasAC[[#This Row],[Código]],INDIRECT("TabelaEntradas[ICMS-ST]")) -> #REF! | K10: =EntradasAC[[#This Row],[Vlr ICMS]] -> #REF! | M10: SEM FORMULA (FORA DO RET) | N10: =EntradasAC[[#This Row],[Vlr ICMS]]-EntradasAC[[#This Row],[Estorno ]] -> #REF!
A11: 243 | B11: COMPRA DE MERCADORIA / ST REVENDA (FORA) | C11: =SUMIF(INDIRECT("TabelaEntradas[AC]"),EntradasAC[[#This Row],[Código]],INDIRECT("TabelaEntradas[VC]")) -> #REF! | D11: =SUMIF(INDIRECT("TabelaEntradas[AC]"),EntradasAC[[#This Row],[Código]],INDIRECT("TabelaEntradas[VC]")) -> #REF! | E11: =SUMIF(INDIRECT("TabelaEntradas[AC]"),EntradasAC[[#This Row],[Código]],INDIRECT("TabelaEntradas[VLR-ICMS]")) -> #REF! | H11: =SUMIF(INDIRECT("TabelaEntradas[AC]"),EntradasAC[[#This Row],[Código]],INDIRECT("TabelaEntradas[VLR_IPI]")) -> #REF! | I11: =SUMIF(INDIRECT("TabelaEntradas[AC]"),EntradasAC[[#This Row],[Código]],INDIRECT("TabelaEntradas[BC-ICMS-ST]")) -> #REF! | J11: =SUMIF(INDIRECT("TabelaEntradas[AC]"),EntradasAC[[#This Row],[Código]],INDIRECT("TabelaEntradas[ICMS-ST]")) -> #REF! | K11: =EntradasAC[[#This Row],[Vlr ICMS]] -> #REF! | L11: 0.03 | N11: =EntradasAC[[#This Row],[Vlr ICMS]]-EntradasAC[[#This Row],[Estorno ]] -> #REF!
A12: 224 | B12: ENTRADA DE INDUST. TERCEIRO (FORA ESTADO) | C12: =SUMIF(INDIRECT("TabelaEntradas[AC]"),EntradasAC[[#This Row],[Código]],INDIRECT("TabelaEntradas[VC]")) -> #REF! | D12: =SUMIF(INDIRECT("TabelaEntradas[AC]"),EntradasAC[[#This Row],[Código]],INDIRECT("TabelaEntradas[VC]")) -> #REF! | E12: =SUMIF(INDIRECT("TabelaEntradas[AC]"),EntradasAC[[#This Row],[Código]],INDIRECT("TabelaEntradas[VLR-ICMS]")) -> #REF! | H12: =SUMIF(INDIRECT("TabelaEntradas[AC]"),EntradasAC[[#This Row],[Código]],INDIRECT("TabelaEntradas[VLR_IPI]")) -> #REF! | I12: =SUMIF(INDIRECT("TabelaEntradas[AC]"),EntradasAC[[#This Row],[Código]],INDIRECT("TabelaEntradas[BC-ICMS-ST]")) -> #REF! | J12: =SUMIF(INDIRECT("TabelaEntradas[AC]"),EntradasAC[[#This Row],[Código]],INDIRECT("TabelaEntradas[ICMS-ST]")) -> #REF! | K12: =EntradasAC[[#This Row],[Vlr ICMS]] -> #REF! | M12: SEM FORMULA (FORA DO RET) | N12: =EntradasAC[[#This Row],[Vlr ICMS]]-EntradasAC[[#This Row],[Estorno ]] -> #REF!
A13: 251 | B13: COMPRA ATIVO (MÁQ. E EQUIP) - FORA | C13: =SUMIF(INDIRECT("TabelaEntradas[AC]"),EntradasAC[[#This Row],[Código]],INDIRECT("TabelaEntradas[VC]")) -> #REF! | D13: =SUMIF(INDIRECT("TabelaEntradas[AC]"),EntradasAC[[#This Row],[Código]],INDIRECT("TabelaEntradas[VC]")) -> #REF! | E13: =SUMIF(INDIRECT("TabelaEntradas[AC]"),EntradasAC[[#This Row],[Código]],INDIRECT("TabelaEntradas[VLR-ICMS]")) -> #REF! | H13: =SUMIF(INDIRECT("TabelaEntradas[AC]"),EntradasAC[[#This Row],[Código]],INDIRECT("TabelaEntradas[VLR_IPI]")) -> #REF! | I13: =SUMIF(INDIRECT("TabelaEntradas[AC]"),EntradasAC[[#This Row],[Código]],INDIRECT("TabelaEntradas[BC-ICMS-ST]")) -> #REF! | J13: =SUMIF(INDIRECT("TabelaEntradas[AC]"),EntradasAC[[#This Row],[Código]],INDIRECT("TabelaEntradas[ICMS-ST]")) -> #REF! | K13: =EntradasAC[[#This Row],[Vlr ICMS]] -> #REF! | M13: SEM FORMULA (FORA DO RET) | N13: =EntradasAC[[#This Row],[Vlr ICMS]]-EntradasAC[[#This Row],[Estorno ]] -> #REF!
A14: 259 | B14: COMPRA ATIVO (INSTALAÇOES) - FORA | C14: =SUMIF(INDIRECT("TabelaEntradas[AC]"),EntradasAC[[#This Row],[Código]],INDIRECT("TabelaEntradas[VC]")) -> #REF! | D14: =SUMIF(INDIRECT("TabelaEntradas[AC]"),EntradasAC[[#This Row],[Código]],INDIRECT("TabelaEntradas[VC]")) -> #REF! | E14: =SUMIF(INDIRECT("TabelaEntradas[AC]"),EntradasAC[[#This Row],[Código]],INDIRECT("TabelaEntradas[VLR-ICMS]")) -> #REF! | H14: =SUMIF(INDIRECT("TabelaEntradas[AC]"),EntradasAC[[#This Row],[Código]],INDIRECT("TabelaEntradas[VLR_IPI]")) -> #REF! | I14: =SUMIF(INDIRECT("TabelaEntradas[AC]"),EntradasAC[[#This Row],[Código]],INDIRECT("TabelaEntradas[BC-ICMS-ST]")) -> #REF! | J14: =SUMIF(INDIRECT("TabelaEntradas[AC]"),EntradasAC[[#This Row],[Código]],INDIRECT("TabelaEntradas[ICMS-ST]")) -> #REF! | K14: =EntradasAC[[#This Row],[Vlr ICMS]] -> #REF! | L14: 0.14 | N14: =EntradasAC[[#This Row],[Vlr ICMS]]-EntradasAC[[#This Row],[Estorno ]] -> #REF!
A15: 253 | B15: COMPRA ATIVO (COMP. E PERI.) - FORA | C15: =SUMIF(INDIRECT("TabelaEntradas[AC]"),EntradasAC[[#This Row],[Código]],INDIRECT("TabelaEntradas[VC]")) -> #REF! | D15: =SUMIF(INDIRECT("TabelaEntradas[AC]"),EntradasAC[[#This Row],[Código]],INDIRECT("TabelaEntradas[VC]")) -> #REF! | E15: =SUMIF(INDIRECT("TabelaEntradas[AC]"),EntradasAC[[#This Row],[Código]],INDIRECT("TabelaEntradas[VLR-ICMS]")) -> #REF! | H15: =SUMIF(INDIRECT("TabelaEntradas[AC]"),EntradasAC[[#This Row],[Código]],INDIRECT("TabelaEntradas[VLR_IPI]")) -> #REF! | I15: =SUMIF(INDIRECT("TabelaEntradas[AC]"),EntradasAC[[#This Row],[Código]],INDIRECT("TabelaEntradas[BC-ICMS-ST]")) -> #REF! | J15: =SUMIF(INDIRECT("TabelaEntradas[AC]"),EntradasAC[[#This Row],[Código]],INDIRECT("TabelaEntradas[ICMS-ST]")) -> #REF! | K15: =EntradasAC[[#This Row],[Vlr ICMS]] -> #REF! | L15: 0.015 | N15: =EntradasAC[[#This Row],[Vlr ICMS]]-EntradasAC[[#This Row],[Estorno ]] -> #REF!
A16: 301 | B16: ENTRADA P/ INDUSTRIALIZAÇÃO | C16: =SUMIF(INDIRECT("TabelaEntradas[AC]"),EntradasAC[[#This Row],[Código]],INDIRECT("TabelaEntradas[VC]")) -> #REF! | D16: =SUMIF(INDIRECT("TabelaEntradas[AC]"),EntradasAC[[#This Row],[Código]],INDIRECT("TabelaEntradas[VC]")) -> #REF! | E16: =SUMIF(INDIRECT("TabelaEntradas[AC]"),EntradasAC[[#This Row],[Código]],INDIRECT("TabelaEntradas[VLR-ICMS]")) -> #REF! | H16: =SUMIF(INDIRECT("TabelaEntradas[AC]"),EntradasAC[[#This Row],[Código]],INDIRECT("TabelaEntradas[VLR_IPI]")) -> #REF! | I16: =SUMIF(INDIRECT("TabelaEntradas[AC]"),EntradasAC[[#This Row],[Código]],INDIRECT("TabelaEntradas[BC-ICMS-ST]")) -> #REF! | J16: =SUMIF(INDIRECT("TabelaEntradas[AC]"),EntradasAC[[#This Row],[Código]],INDIRECT("TabelaEntradas[ICMS-ST]")) -> #REF! | K16: =EntradasAC[[#This Row],[Vlr ICMS]] -> #REF! | M16: SEM FORMULA (FORA DO RET) | N16: =EntradasAC[[#This Row],[Vlr ICMS]]-EntradasAC[[#This Row],[Estorno ]] -> #REF!
A17: 302 | B17: ENTRADA EM RETORNO INDUSTRIALIZAÇÃO | C17: =SUMIF(INDIRECT("TabelaEntradas[AC]"),EntradasAC[[#This Row],[Código]],INDIRECT("TabelaEntradas[VC]")) -> #REF! | D17: =SUMIF(INDIRECT("TabelaEntradas[AC]"),EntradasAC[[#This Row],[Código]],INDIRECT("TabelaEntradas[VC]")) -> #REF! | E17: =SUMIF(INDIRECT("TabelaEntradas[AC]"),EntradasAC[[#This Row],[Código]],INDIRECT("TabelaEntradas[VLR-ICMS]")) -> #REF! | H17: =SUMIF(INDIRECT("TabelaEntradas[AC]"),EntradasAC[[#This Row],[Código]],INDIRECT("TabelaEntradas[VLR_IPI]")) -> #REF! | I17: =SUMIF(INDIRECT("TabelaEntradas[AC]"),EntradasAC[[#This Row],[Código]],INDIRECT("TabelaEntradas[BC-ICMS-ST]")) -> #REF! | J17: =SUMIF(INDIRECT("TabelaEntradas[AC]"),EntradasAC[[#This Row],[Código]],INDIRECT("TabelaEntradas[ICMS-ST]")) -> #REF! | K17: =EntradasAC[[#This Row],[Vlr ICMS]] -> #REF! | L17: 0.03 | N17: =EntradasAC[[#This Row],[Vlr ICMS]]-EntradasAC[[#This Row],[Estorno ]] -> #REF!
A18: 308 | B18: ENTRADA EM COMODATO | C18: =SUMIF(INDIRECT("TabelaEntradas[AC]"),EntradasAC[[#This Row],[Código]],INDIRECT("TabelaEntradas[VC]")) -> #REF! | D18: =SUMIF(INDIRECT("TabelaEntradas[AC]"),EntradasAC[[#This Row],[Código]],INDIRECT("TabelaEntradas[VC]")) -> #REF! | E18: =SUMIF(INDIRECT("TabelaEntradas[AC]"),EntradasAC[[#This Row],[Código]],INDIRECT("TabelaEntradas[VLR-ICMS]")) -> #REF! | H18: =SUMIF(INDIRECT("TabelaEntradas[AC]"),EntradasAC[[#This Row],[Código]],INDIRECT("TabelaEntradas[VLR_IPI]")) -> #REF! | I18: =SUMIF(INDIRECT("TabelaEntradas[AC]"),EntradasAC[[#This Row],[Código]],INDIRECT("TabelaEntradas[BC-ICMS-ST]")) -> #REF! | J18: =SUMIF(INDIRECT("TabelaEntradas[AC]"),EntradasAC[[#This Row],[Código]],INDIRECT("TabelaEntradas[ICMS-ST]")) -> #REF! | K18: =EntradasAC[[#This Row],[Vlr ICMS]] -> #REF! | M18: SEM FORMULA (FORA DO RET) | N18: =EntradasAC[[#This Row],[Vlr ICMS]]-EntradasAC[[#This Row],[Estorno ]] -> #REF!
A19: 321 | B19: ENTRADA EM RETORNO DE VASILHAME | C19: =SUMIF(INDIRECT("TabelaEntradas[AC]"),EntradasAC[[#This Row],[Código]],INDIRECT("TabelaEntradas[VC]")) -> #REF! | D19: =SUMIF(INDIRECT("TabelaEntradas[AC]"),EntradasAC[[#This Row],[Código]],INDIRECT("TabelaEntradas[VC]")) -> #REF! | E19: =SUMIF(INDIRECT("TabelaEntradas[AC]"),EntradasAC[[#This Row],[Código]],INDIRECT("TabelaEntradas[VLR-ICMS]")) -> #REF! | H19: =SUMIF(INDIRECT("TabelaEntradas[AC]"),EntradasAC[[#This Row],[Código]],INDIRECT("TabelaEntradas[VLR_IPI]")) -> #REF! | I19: =SUMIF(INDIRECT("TabelaEntradas[AC]"),EntradasAC[[#This Row],[Código]],INDIRECT("TabelaEntradas[BC-ICMS-ST]")) -> #REF! | J19: =SUMIF(INDIRECT("TabelaEntradas[AC]"),EntradasAC[[#This Row],[Código]],INDIRECT("TabelaEntradas[ICMS-ST]")) -> #REF! | K19: =EntradasAC[[#This Row],[Vlr ICMS]] -> #REF! | N19: =EntradasAC[[#This Row],[Vlr ICMS]]-EntradasAC[[#This Row],[Estorno ]] -> #REF!
A20: 324 | B20: ENTRADA P/ INDUSTRIALIZ (CONTA E ORDEM) | C20: =SUMIF(INDIRECT("TabelaEntradas[AC]"),EntradasAC[[#This Row],[Código]],INDIRECT("TabelaEntradas[VC]")) -> #REF! | D20: =SUMIF(INDIRECT("TabelaEntradas[AC]"),EntradasAC[[#This Row],[Código]],INDIRECT("TabelaEntradas[VC]")) -> #REF! | E20: =SUMIF(INDIRECT("TabelaEntradas[AC]"),EntradasAC[[#This Row],[Código]],INDIRECT("TabelaEntradas[VLR-ICMS]")) -> #REF! | H20: =SUMIF(INDIRECT("TabelaEntradas[AC]"),EntradasAC[[#This Row],[Código]],INDIRECT("TabelaEntradas[VLR_IPI]")) -> #REF! | I20: =SUMIF(INDIRECT("TabelaEntradas[AC]"),EntradasAC[[#This Row],[Código]],INDIRECT("TabelaEntradas[BC-ICMS-ST]")) -> #REF! | J20: =SUMIF(INDIRECT("TabelaEntradas[AC]"),EntradasAC[[#This Row],[Código]],INDIRECT("TabelaEntradas[ICMS-ST]")) -> #REF! | K20: =EntradasAC[[#This Row],[Vlr ICMS]] -> #REF! | M20: SEM FORMULA (FORA DO RET) | N20: =EntradasAC[[#This Row],[Vlr ICMS]]-EntradasAC[[#This Row],[Estorno ]] -> #REF!
A21: 349 | B21: OUTRAS ENTRADAS | C21: =SUMIF(INDIRECT("TabelaEntradas[AC]"),EntradasAC[[#This Row],[Código]],INDIRECT("TabelaEntradas[VC]")) -> #REF! | D21: =SUMIF(INDIRECT("TabelaEntradas[AC]"),EntradasAC[[#This Row],[Código]],INDIRECT("TabelaEntradas[VC]")) -> #REF! | E21: =SUMIF(INDIRECT("TabelaEntradas[AC]"),EntradasAC[[#This Row],[Código]],INDIRECT("TabelaEntradas[VLR-ICMS]")) -> #REF! | H21: =SUMIF(INDIRECT("TabelaEntradas[AC]"),EntradasAC[[#This Row],[Código]],INDIRECT("TabelaEntradas[VLR_IPI]")) -> #REF! | I21: =SUMIF(INDIRECT("TabelaEntradas[AC]"),EntradasAC[[#This Row],[Código]],INDIRECT("TabelaEntradas[BC-ICMS-ST]")) -> #REF! | J21: =SUMIF(INDIRECT("TabelaEntradas[AC]"),EntradasAC[[#This Row],[Código]],INDIRECT("TabelaEntradas[ICMS-ST]")) -> #REF! | K21: =EntradasAC[[#This Row],[Vlr ICMS]] -> #REF! | M21: SEM FORMULA (FORA DO RET) | N21: =EntradasAC[[#This Row],[Vlr ICMS]]-EntradasAC[[#This Row],[Estorno ]] -> #REF!
A22: 453 | B22: ENTRADA EM TRANFERENCIA USO E CONSUMO | C22: =SUMIF(INDIRECT("TabelaEntradas[AC]"),EntradasAC[[#This Row],[Código]],INDIRECT("TabelaEntradas[VC]")) -> #REF! | D22: =SUMIF(INDIRECT("TabelaEntradas[AC]"),EntradasAC[[#This Row],[Código]],INDIRECT("TabelaEntradas[VC]")) -> #REF! | E22: =SUMIF(INDIRECT("TabelaEntradas[AC]"),EntradasAC[[#This Row],[Código]],INDIRECT("TabelaEntradas[VLR-ICMS]")) -> #REF! | H22: =SUMIF(INDIRECT("TabelaEntradas[AC]"),EntradasAC[[#This Row],[Código]],INDIRECT("TabelaEntradas[VLR_IPI]")) -> #REF! | I22: =SUMIF(INDIRECT("TabelaEntradas[AC]"),EntradasAC[[#This Row],[Código]],INDIRECT("TabelaEntradas[BC-ICMS-ST]")) -> #REF! | J22: =SUMIF(INDIRECT("TabelaEntradas[AC]"),EntradasAC[[#This Row],[Código]],INDIRECT("TabelaEntradas[ICMS-ST]")) -> #REF! | K22: =EntradasAC[[#This Row],[Vlr ICMS]] -> #REF! | M22: SEM FORMULA (FORA DO RET) | N22: =EntradasAC[[#This Row],[Vlr ICMS]]-EntradasAC[[#This Row],[Estorno ]] -> #REF!
A23: 410 | B23: DEVOLUÇÃO DE VENDA (ST) | C23: =SUMIF(INDIRECT("TabelaEntradas[AC]"),EntradasAC[[#This Row],[Código]],INDIRECT("TabelaEntradas[VC]")) -> #REF! | D23: =SUMIF(INDIRECT("TabelaEntradas[AC]"),EntradasAC[[#This Row],[Código]],INDIRECT("TabelaEntradas[VC]")) -> #REF! | E23: =SUMIF(INDIRECT("TabelaEntradas[AC]"),EntradasAC[[#This Row],[Código]],INDIRECT("TabelaEntradas[VLR-ICMS]")) -> #REF! | H23: =SUMIF(INDIRECT("TabelaEntradas[AC]"),EntradasAC[[#This Row],[Código]],INDIRECT("TabelaEntradas[VLR_IPI]")) -> #REF! | I23: =SUMIF(INDIRECT("TabelaEntradas[AC]"),EntradasAC[[#This Row],[Código]],INDIRECT("TabelaEntradas[BC-ICMS-ST]")) -> #REF! | J23: =SUMIF(INDIRECT("TabelaEntradas[AC]"),EntradasAC[[#This Row],[Código]],INDIRECT("TabelaEntradas[ICMS-ST]")) -> #REF! | K23: =EntradasAC[[#This Row],[Vlr ICMS]] -> #REF! | M23: SEM FORMULA (FORA DO RET) | N23: =EntradasAC[[#This Row],[Vlr ICMS]]-EntradasAC[[#This Row],[Estorno ]] -> #REF!
A24: 1200 | B24: DEVOLUÇÃO VENDA - RET | C24: =SUMIF(INDIRECT("TabelaEntradas[AC]"),EntradasAC[[#This Row],[Código]],INDIRECT("TabelaEntradas[VC]")) -> #REF! | D24: =SUMIF(INDIRECT("TabelaEntradas[AC]"),EntradasAC[[#This Row],[Código]],INDIRECT("TabelaEntradas[VC]")) -> #REF! | E24: =SUMIF(INDIRECT("TabelaEntradas[AC]"),EntradasAC[[#This Row],[Código]],INDIRECT("TabelaEntradas[VLR-ICMS]")) -> #REF! | H24: =SUMIF(INDIRECT("TabelaEntradas[AC]"),EntradasAC[[#This Row],[Código]],INDIRECT("TabelaEntradas[VLR_IPI]")) -> #REF! | I24: =SUMIF(INDIRECT("TabelaEntradas[AC]"),EntradasAC[[#This Row],[Código]],INDIRECT("TabelaEntradas[BC-ICMS-ST]")) -> #REF! | J24: =SUMIF(INDIRECT("TabelaEntradas[AC]"),EntradasAC[[#This Row],[Código]],INDIRECT("TabelaEntradas[ICMS-ST]")) -> #REF! | K24: =EntradasAC[[#This Row],[Vlr ICMS]]-EntradasAC[[#This Row],[Base ICMS]]*3% -> #REF! | L24: 3% | N24: =EntradasAC[[#This Row],[Vlr ICMS]]-EntradasAC[[#This Row],[Estorno ]] -> #REF!
A25: 4110 | B25: DEVOLUÇÃO DE VENDA (ST) - RET | C25: =SUMIF(INDIRECT("TabelaEntradas[AC]"),EntradasAC[[#This Row],[Código]],INDIRECT("TabelaEntradas[VC]")) -> #REF! | D25: =SUMIF(INDIRECT("TabelaEntradas[AC]"),EntradasAC[[#This Row],[Código]],INDIRECT("TabelaEntradas[VC]")) -> #REF! | E25: =SUMIF(INDIRECT("TabelaEntradas[AC]"),EntradasAC[[#This Row],[Código]],INDIRECT("TabelaEntradas[VLR-ICMS]")) -> #REF! | H25: =SUMIF(INDIRECT("TabelaEntradas[AC]"),EntradasAC[[#This Row],[Código]],INDIRECT("TabelaEntradas[VLR_IPI]")) -> #REF! | I25: =SUMIF(INDIRECT("TabelaEntradas[AC]"),EntradasAC[[#This Row],[Código]],INDIRECT("TabelaEntradas[BC-ICMS-ST]")) -> #REF! | J25: =SUMIF(INDIRECT("TabelaEntradas[AC]"),EntradasAC[[#This Row],[Código]],INDIRECT("TabelaEntradas[ICMS-ST]")) -> #REF! | K25: =EntradasAC[[#This Row],[Vlr ICMS]] -> #REF! | M25: SEM FORMULA (FORA DO RET) | N25: =EntradasAC[[#This Row],[Vlr ICMS]]-EntradasAC[[#This Row],[Estorno ]] -> #REF!
A26: 452 | B26: ENTRADA EM TRANFERENCIA P/ COMERCIALIZAÇÃO | C26: =SUMIF(INDIRECT("TabelaEntradas[AC]"),EntradasAC[[#This Row],[Código]],INDIRECT("TabelaEntradas[VC]")) -> #REF! | D26: =SUMIF(INDIRECT("TabelaEntradas[AC]"),EntradasAC[[#This Row],[Código]],INDIRECT("TabelaEntradas[VC]")) -> #REF! | E26: =SUMIF(INDIRECT("TabelaEntradas[AC]"),EntradasAC[[#This Row],[Código]],INDIRECT("TabelaEntradas[VLR-ICMS]")) -> #REF! | H26: =SUMIF(INDIRECT("TabelaEntradas[AC]"),EntradasAC[[#This Row],[Código]],INDIRECT("TabelaEntradas[VLR_IPI]")) -> #REF! | I26: =SUMIF(INDIRECT("TabelaEntradas[AC]"),EntradasAC[[#This Row],[Código]],INDIRECT("TabelaEntradas[BC-ICMS-ST]")) -> #REF! | J26: =SUMIF(INDIRECT("TabelaEntradas[AC]"),EntradasAC[[#This Row],[Código]],INDIRECT("TabelaEntradas[ICMS-ST]")) -> #REF! | K26: =EntradasAC[[#This Row],[Vlr ICMS]] -> #REF! | M26: SEM FORMULA (FORA DO RET) | N26: =EntradasAC[[#This Row],[Vlr ICMS]]-EntradasAC[[#This Row],[Estorno ]] -> #REF!
A27: 455 | B27: ENTRADA EM TRANSFERENCIA DE ATIVO | C27: =SUMIF(INDIRECT("TabelaEntradas[AC]"),EntradasAC[[#This Row],[Código]],INDIRECT("TabelaEntradas[VC]")) -> #REF! | D27: =SUMIF(INDIRECT("TabelaEntradas[AC]"),EntradasAC[[#This Row],[Código]],INDIRECT("TabelaEntradas[VC]")) -> #REF! | E27: =SUMIF(INDIRECT("TabelaEntradas[AC]"),EntradasAC[[#This Row],[Código]],INDIRECT("TabelaEntradas[VLR-ICMS]")) -> #REF! | H27: =SUMIF(INDIRECT("TabelaEntradas[AC]"),EntradasAC[[#This Row],[Código]],INDIRECT("TabelaEntradas[VLR_IPI]")) -> #REF! | I27: =SUMIF(INDIRECT("TabelaEntradas[AC]"),EntradasAC[[#This Row],[Código]],INDIRECT("TabelaEntradas[BC-ICMS-ST]")) -> #REF! | J27: =SUMIF(INDIRECT("TabelaEntradas[AC]"),EntradasAC[[#This Row],[Código]],INDIRECT("TabelaEntradas[ICMS-ST]")) -> #REF! | K27: =EntradasAC[[#This Row],[Vlr ICMS]] -> #REF! | N27: =EntradasAC[[#This Row],[Vlr ICMS]]-EntradasAC[[#This Row],[Estorno ]] -> #REF!
A28: 4052 | B28: ENTRADA EM TRANFERENCIA P/ COMERCIALIZAÇÃO (RET) | C28: =SUMIF(INDIRECT("TabelaEntradas[AC]"),EntradasAC[[#This Row],[Código]],INDIRECT("TabelaEntradas[VC]")) -> #REF! | D28: =SUMIF(INDIRECT("TabelaEntradas[AC]"),EntradasAC[[#This Row],[Código]],INDIRECT("TabelaEntradas[VC]")) -> #REF! | E28: =SUMIF(INDIRECT("TabelaEntradas[AC]"),EntradasAC[[#This Row],[Código]],INDIRECT("TabelaEntradas[VLR-ICMS]")) -> #REF! | H28: =SUMIF(INDIRECT("TabelaEntradas[AC]"),EntradasAC[[#This Row],[Código]],INDIRECT("TabelaEntradas[VLR_IPI]")) -> #REF! | I28: =SUMIF(INDIRECT("TabelaEntradas[AC]"),EntradasAC[[#This Row],[Código]],INDIRECT("TabelaEntradas[BC-ICMS-ST]")) -> #REF! | J28: =SUMIF(INDIRECT("TabelaEntradas[AC]"),EntradasAC[[#This Row],[Código]],INDIRECT("TabelaEntradas[ICMS-ST]")) -> #REF! | K28: =EntradasAC[[#This Row],[Vlr ICMS]] -> #REF! | M28: ESTORNA TUDO | N28: =EntradasAC[[#This Row],[Vlr ICMS]]-EntradasAC[[#This Row],[Estorno ]] -> #REF!
A29: 4100 | B29: DEVOLUÇÃO DE REVENDA (ST) - RET | C29: =SUMIF(INDIRECT("TabelaEntradas[AC]"),EntradasAC[[#This Row],[Código]],INDIRECT("TabelaEntradas[VC]")) -> #REF! | D29: =SUMIF(INDIRECT("TabelaEntradas[AC]"),EntradasAC[[#This Row],[Código]],INDIRECT("TabelaEntradas[VC]")) -> #REF! | E29: =SUMIF(INDIRECT("TabelaEntradas[AC]"),EntradasAC[[#This Row],[Código]],INDIRECT("TabelaEntradas[VLR-ICMS]")) -> #REF! | H29: =SUMIF(INDIRECT("TabelaEntradas[AC]"),EntradasAC[[#This Row],[Código]],INDIRECT("TabelaEntradas[VLR_IPI]")) -> #REF! | I29: =SUMIF(INDIRECT("TabelaEntradas[AC]"),EntradasAC[[#This Row],[Código]],INDIRECT("TabelaEntradas[BC-ICMS-ST]")) -> #REF! | J29: =SUMIF(INDIRECT("TabelaEntradas[AC]"),EntradasAC[[#This Row],[Código]],INDIRECT("TabelaEntradas[ICMS-ST]")) -> #REF! | K29: =EntradasAC[[#This Row],[Vlr ICMS]]-EntradasAC[[#This Row],[Base ICMS]]*3% -> #REF! | L29: 3% | N29: =EntradasAC[[#This Row],[Vlr ICMS]]-EntradasAC[[#This Row],[Estorno ]] -> #REF!
A30: 1561 | B30: DESPESA C/ MAT. DE LIMPEZA | C30: =SUMIF(INDIRECT("TabelaEntradas[AC]"),EntradasAC[[#This Row],[Código]],INDIRECT("TabelaEntradas[VC]")) -> #REF! | D30: =SUMIF(INDIRECT("TabelaEntradas[AC]"),EntradasAC[[#This Row],[Código]],INDIRECT("TabelaEntradas[VC]")) -> #REF! | E30: =SUMIF(INDIRECT("TabelaEntradas[AC]"),EntradasAC[[#This Row],[Código]],INDIRECT("TabelaEntradas[VLR-ICMS]")) -> #REF! | H30: =SUMIF(INDIRECT("TabelaEntradas[AC]"),EntradasAC[[#This Row],[Código]],INDIRECT("TabelaEntradas[VLR_IPI]")) -> #REF! | I30: =SUMIF(INDIRECT("TabelaEntradas[AC]"),EntradasAC[[#This Row],[Código]],INDIRECT("TabelaEntradas[BC-ICMS-ST]")) -> #REF! | J30: =SUMIF(INDIRECT("TabelaEntradas[AC]"),EntradasAC[[#This Row],[Código]],INDIRECT("TabelaEntradas[ICMS-ST]")) -> #REF! | K30: =EntradasAC[[#This Row],[Vlr ICMS]] -> #REF! | M30: SEM FORMULA (FORA DO RET) | N30: =EntradasAC[[#This Row],[Vlr ICMS]]-EntradasAC[[#This Row],[Estorno ]] -> #REF!
A31: 1201 | B31: DEVOLUÇÃO VENDA - RET | C31: =SUMIF(INDIRECT("TabelaEntradas[AC]"),EntradasAC[[#This Row],[Código]],INDIRECT("TabelaEntradas[VC]")) -> #REF! | D31: =SUMIF(INDIRECT("TabelaEntradas[AC]"),EntradasAC[[#This Row],[Código]],INDIRECT("TabelaEntradas[VC]")) -> #REF! | E31: =SUMIF(INDIRECT("TabelaEntradas[AC]"),EntradasAC[[#This Row],[Código]],INDIRECT("TabelaEntradas[VLR-ICMS]")) -> #REF! | H31: =SUMIF(INDIRECT("TabelaEntradas[AC]"),EntradasAC[[#This Row],[Código]],INDIRECT("TabelaEntradas[VLR_IPI]")) -> #REF! | I31: =SUMIF(INDIRECT("TabelaEntradas[AC]"),EntradasAC[[#This Row],[Código]],INDIRECT("TabelaEntradas[BC-ICMS-ST]")) -> #REF! | J31: =SUMIF(INDIRECT("TabelaEntradas[AC]"),EntradasAC[[#This Row],[Código]],INDIRECT("TabelaEntradas[ICMS-ST]")) -> #REF! | K31: =EntradasAC[[#This Row],[Vlr ICMS]] -> #REF! | M31: SEM FORMULA (FORA DO RET) | N31: =EntradasAC[[#This Row],[Vlr ICMS]]-EntradasAC[[#This Row],[Estorno ]] -> #REF!
A32: 1562 | B32: DESPESA C/ COPA, COZINHA E REFEITORIO | C32: =SUMIF(INDIRECT("TabelaEntradas[AC]"),EntradasAC[[#This Row],[Código]],INDIRECT("TabelaEntradas[VC]")) -> #REF! | D32: =SUMIF(INDIRECT("TabelaEntradas[AC]"),EntradasAC[[#This Row],[Código]],INDIRECT("TabelaEntradas[VC]")) -> #REF! | E32: =SUMIF(INDIRECT("TabelaEntradas[AC]"),EntradasAC[[#This Row],[Código]],INDIRECT("TabelaEntradas[VLR-ICMS]")) -> #REF! | H32: =SUMIF(INDIRECT("TabelaEntradas[AC]"),EntradasAC[[#This Row],[Código]],INDIRECT("TabelaEntradas[VLR_IPI]")) -> #REF! | I32: =SUMIF(INDIRECT("TabelaEntradas[AC]"),EntradasAC[[#This Row],[Código]],INDIRECT("TabelaEntradas[BC-ICMS-ST]")) -> #REF! | J32: =SUMIF(INDIRECT("TabelaEntradas[AC]"),EntradasAC[[#This Row],[Código]],INDIRECT("TabelaEntradas[ICMS-ST]")) -> #REF! | K32: =EntradasAC[[#This Row],[Vlr ICMS]] -> #REF! | M32: SEM FORMULA (FORA DO RET) | N32: =EntradasAC[[#This Row],[Vlr ICMS]]-EntradasAC[[#This Row],[Estorno ]] -> #REF!
A33: 1564 | B33: DESPESA C/ MAT.CONSUMO/INTERM/SECUNDÁRIO | C33: =SUMIF(INDIRECT("TabelaEntradas[AC]"),EntradasAC[[#This Row],[Código]],INDIRECT("TabelaEntradas[VC]")) -> #REF! | D33: =SUMIF(INDIRECT("TabelaEntradas[AC]"),EntradasAC[[#This Row],[Código]],INDIRECT("TabelaEntradas[VC]")) -> #REF! | E33: =SUMIF(INDIRECT("TabelaEntradas[AC]"),EntradasAC[[#This Row],[Código]],INDIRECT("TabelaEntradas[VLR-ICMS]")) -> #REF! | H33: =SUMIF(INDIRECT("TabelaEntradas[AC]"),EntradasAC[[#This Row],[Código]],INDIRECT("TabelaEntradas[VLR_IPI]")) -> #REF! | I33: =SUMIF(INDIRECT("TabelaEntradas[AC]"),EntradasAC[[#This Row],[Código]],INDIRECT("TabelaEntradas[BC-ICMS-ST]")) -> #REF! | J33: =SUMIF(INDIRECT("TabelaEntradas[AC]"),EntradasAC[[#This Row],[Código]],INDIRECT("TabelaEntradas[ICMS-ST]")) -> #REF! | K33: =EntradasAC[[#This Row],[Vlr ICMS]] -> #REF! | M33: SEM FORMULA (FORA DO RET) | N33: =EntradasAC[[#This Row],[Vlr ICMS]]-EntradasAC[[#This Row],[Estorno ]] -> #REF!
A34: 1565 | B34: DESPESA COM VEÍCULO | C34: =SUMIF(INDIRECT("TabelaEntradas[AC]"),EntradasAC[[#This Row],[Código]],INDIRECT("TabelaEntradas[VC]")) -> #REF! | D34: =SUMIF(INDIRECT("TabelaEntradas[AC]"),EntradasAC[[#This Row],[Código]],INDIRECT("TabelaEntradas[VC]")) -> #REF! | E34: =SUMIF(INDIRECT("TabelaEntradas[AC]"),EntradasAC[[#This Row],[Código]],INDIRECT("TabelaEntradas[VLR-ICMS]")) -> #REF! | H34: =SUMIF(INDIRECT("TabelaEntradas[AC]"),EntradasAC[[#This Row],[Código]],INDIRECT("TabelaEntradas[VLR_IPI]")) -> #REF! | I34: =SUMIF(INDIRECT("TabelaEntradas[AC]"),EntradasAC[[#This Row],[Código]],INDIRECT("TabelaEntradas[BC-ICMS-ST]")) -> #REF! | J34: =SUMIF(INDIRECT("TabelaEntradas[AC]"),EntradasAC[[#This Row],[Código]],INDIRECT("TabelaEntradas[ICMS-ST]")) -> #REF! | K34: =EntradasAC[[#This Row],[Vlr ICMS]] -> #REF! | N34: =EntradasAC[[#This Row],[Vlr ICMS]]-EntradasAC[[#This Row],[Estorno ]] -> #REF!
A35: 1568 | B35: DESPESA C/ MANUT. DE BENS E INST. | C35: =SUMIF(INDIRECT("TabelaEntradas[AC]"),EntradasAC[[#This Row],[Código]],INDIRECT("TabelaEntradas[VC]")) -> #REF! | D35: =SUMIF(INDIRECT("TabelaEntradas[AC]"),EntradasAC[[#This Row],[Código]],INDIRECT("TabelaEntradas[VC]")) -> #REF! | E35: =SUMIF(INDIRECT("TabelaEntradas[AC]"),EntradasAC[[#This Row],[Código]],INDIRECT("TabelaEntradas[VLR-ICMS]")) -> #REF! | H35: =SUMIF(INDIRECT("TabelaEntradas[AC]"),EntradasAC[[#This Row],[Código]],INDIRECT("TabelaEntradas[VLR_IPI]")) -> #REF! | I35: =SUMIF(INDIRECT("TabelaEntradas[AC]"),EntradasAC[[#This Row],[Código]],INDIRECT("TabelaEntradas[BC-ICMS-ST]")) -> #REF! | J35: =SUMIF(INDIRECT("TabelaEntradas[AC]"),EntradasAC[[#This Row],[Código]],INDIRECT("TabelaEntradas[ICMS-ST]")) -> #REF! | K35: =EntradasAC[[#This Row],[Vlr ICMS]] -> #REF! | M35: SEM FORMULA (FORA DO RET) | N35: =EntradasAC[[#This Row],[Vlr ICMS]]-EntradasAC[[#This Row],[Estorno ]] -> #REF!
A36: 2560 | B36: DESPESA C/ MATERIAL ESCRITÓRIO (FORA) | C36: =SUMIF(INDIRECT("TabelaEntradas[AC]"),EntradasAC[[#This Row],[Código]],INDIRECT("TabelaEntradas[VC]")) -> #REF! | D36: =SUMIF(INDIRECT("TabelaEntradas[AC]"),EntradasAC[[#This Row],[Código]],INDIRECT("TabelaEntradas[VC]")) -> #REF! | E36: =SUMIF(INDIRECT("TabelaEntradas[AC]"),EntradasAC[[#This Row],[Código]],INDIRECT("TabelaEntradas[VLR-ICMS]")) -> #REF! | H36: =SUMIF(INDIRECT("TabelaEntradas[AC]"),EntradasAC[[#This Row],[Código]],INDIRECT("TabelaEntradas[VLR_IPI]")) -> #REF! | I36: =SUMIF(INDIRECT("TabelaEntradas[AC]"),EntradasAC[[#This Row],[Código]],INDIRECT("TabelaEntradas[BC-ICMS-ST]")) -> #REF! | J36: =SUMIF(INDIRECT("TabelaEntradas[AC]"),EntradasAC[[#This Row],[Código]],INDIRECT("TabelaEntradas[ICMS-ST]")) -> #REF! | K36: =EntradasAC[[#This Row],[Vlr ICMS]] -> #REF! | M36: SEM FORMULA (FORA DO RET) | N36: =EntradasAC[[#This Row],[Vlr ICMS]]-EntradasAC[[#This Row],[Estorno ]] -> #REF!
A37: 2564 | B37: DESPESA C/ MAT.CONSUMO (FORA) | C37: =SUMIF(INDIRECT("TabelaEntradas[AC]"),EntradasAC[[#This Row],[Código]],INDIRECT("TabelaEntradas[VC]")) -> #REF! | D37: =SUMIF(INDIRECT("TabelaEntradas[AC]"),EntradasAC[[#This Row],[Código]],INDIRECT("TabelaEntradas[VC]")) -> #REF! | E37: =SUMIF(INDIRECT("TabelaEntradas[AC]"),EntradasAC[[#This Row],[Código]],INDIRECT("TabelaEntradas[VLR-ICMS]")) -> #REF! | H37: =SUMIF(INDIRECT("TabelaEntradas[AC]"),EntradasAC[[#This Row],[Código]],INDIRECT("TabelaEntradas[VLR_IPI]")) -> #REF! | I37: =SUMIF(INDIRECT("TabelaEntradas[AC]"),EntradasAC[[#This Row],[Código]],INDIRECT("TabelaEntradas[BC-ICMS-ST]")) -> #REF! | J37: =SUMIF(INDIRECT("TabelaEntradas[AC]"),EntradasAC[[#This Row],[Código]],INDIRECT("TabelaEntradas[ICMS-ST]")) -> #REF! | K37: =EntradasAC[[#This Row],[Vlr ICMS]] -> #REF! | M37: SEM FORMULA (FORA DO RET) | N37: =EntradasAC[[#This Row],[Vlr ICMS]]-EntradasAC[[#This Row],[Estorno ]] -> #REF!
A38: 2568 | B38: DESPESA C/ MANUT. DE BENS E INST. (FORA) | C38: =SUMIF(INDIRECT("TabelaEntradas[AC]"),EntradasAC[[#This Row],[Código]],INDIRECT("TabelaEntradas[VC]")) -> #REF! | D38: =SUMIF(INDIRECT("TabelaEntradas[AC]"),EntradasAC[[#This Row],[Código]],INDIRECT("TabelaEntradas[VC]")) -> #REF! | E38: =SUMIF(INDIRECT("TabelaEntradas[AC]"),EntradasAC[[#This Row],[Código]],INDIRECT("TabelaEntradas[VLR-ICMS]")) -> #REF! | H38: =SUMIF(INDIRECT("TabelaEntradas[AC]"),EntradasAC[[#This Row],[Código]],INDIRECT("TabelaEntradas[VLR_IPI]")) -> #REF! | I38: =SUMIF(INDIRECT("TabelaEntradas[AC]"),EntradasAC[[#This Row],[Código]],INDIRECT("TabelaEntradas[BC-ICMS-ST]")) -> #REF! | J38: =SUMIF(INDIRECT("TabelaEntradas[AC]"),EntradasAC[[#This Row],[Código]],INDIRECT("TabelaEntradas[ICMS-ST]")) -> #REF! | K38: =EntradasAC[[#This Row],[Vlr ICMS]] -> #REF! | M38: SEM FORMULA (FORA DO RET) | N38: =EntradasAC[[#This Row],[Vlr ICMS]]-EntradasAC[[#This Row],[Estorno ]] -> #REF!
A39: Total | C39: =SUBTOTAL(109,EntradasAC[Vlr Contábil]) -> #REF! | D39: =SUBTOTAL(109,EntradasAC[Base ICMS]) -> #REF! | E39: =SUBTOTAL(109,EntradasAC[Vlr ICMS]) -> #REF! | F39: =SUBTOTAL(109,EntradasAC[Isentas ICMS]) -> 0 | G39: =SUBTOTAL(109,EntradasAC[Outras ICMS]) -> 0 | H39: =SUBTOTAL(109,EntradasAC[Vlr IPI]) -> #REF! | I39: =SUBTOTAL(109,EntradasAC[BC ICMS ST]) -> #REF! | J39: =SUBTOTAL(109,EntradasAC[Vlr ICMS ST]) -> #REF! | K39: =SUM(EntradasAC[[Estorno ]])-K24-K29 -> #REF! | N39: =SUBTOTAL(109,EntradasAC[ESTORNO DEV]) -> #REF!

Sheet Apuração_ICMS
A1: HIGIETOP
A2: OPERAÇÕES INCENTIVADAS - PTA nº 45.000036597-04 | D2: =SUBTOTAL(9,D4:D20) -> #REF! | E2: =SUBTOTAL(9,E4:E20) -> #REF! | F2: =SUBTOTAL(9,F4:F20) -> #REF! | H2: =SUBTOTAL(9,H4:H20) -> #REF! | I2: =SUBTOTAL(9,I4:I20) -> #REF!
A3: ACUMULADOR | C3: DESCRIÇÃO | D3: VLR_OPERACAO | E3: BC ICMS | F3: Débitos ICMS | G3: % Rec Efetivo: | H3: Crédito PTA | I3: ICMS RET
A4: 8054 | B4: C1 | C4: TRANSFERENCIA IMPORTADOS - INTERESTADUAL (4%) | D4: =SUMIF(INDIRECT("TabelaSaidas[AC]"),Apuração_ICMS!A4,INDIRECT("TabelaSaidas[VC_ITEM]")) -> #REF! | E4: =SUMIF(INDIRECT("TabelaSaidas[AC]"),Apuração_ICMS!A4,INDIRECT("TabelaSaidas[BC_ICMS]")) -> #REF! | F4: =SUMIF(INDIRECT("TabelaSaidas[AC]"),Apuração_ICMS!A4,INDIRECT("TabelaSaidas[ICMS]")) -> #REF! | G4: 0.015 | H4: =F4-I4 -> #REF! | I4: =E4*G4 -> #REF!
A5: 5074 | C5: REVENDA NAC - INTERNA - NÃO CONTRIB(18%) | D5: =SUMIF(INDIRECT("TabelaSaidas[AC]"),Apuração_ICMS!A5,INDIRECT("TabelaSaidas[VC_ITEM]")) -> #REF! | E5: =SUMIF(INDIRECT("TabelaSaidas[AC]"),Apuração_ICMS!A5,INDIRECT("TabelaSaidas[BC_ICMS]")) -> #REF! | F5: =SUMIF(INDIRECT("TabelaSaidas[AC]"),Apuração_ICMS!A5,INDIRECT("TabelaSaidas[ICMS]")) -> #REF! | H5: =F5-I5 -> #REF! | I5: =E5*G5 -> #REF! | J5: % Rec Efetivo: | K5: BC ICMS | L5: ICMS RET
A6: 5075 | C6: REVENDA NAC - INTERNA - NÃO CONTRIB(25%) | D6: =SUMIF(INDIRECT("TabelaSaidas[AC]"),Apuração_ICMS!A6,INDIRECT("TabelaSaidas[VC_ITEM]")) -> #REF! | E6: =SUMIF(INDIRECT("TabelaSaidas[AC]"),Apuração_ICMS!A6,INDIRECT("TabelaSaidas[BC_ICMS]")) -> #REF! | F6: =SUMIF(INDIRECT("TabelaSaidas[AC]"),Apuração_ICMS!A6,INDIRECT("TabelaSaidas[ICMS]")) -> #REF! | H6: =F6-I6 -> #REF! | I6: =E6*G6 -> #REF! | J6: 0.015 | K6: =SUMIF(G4:G20,J6,E4:E20) -> #REF! | L6: =SUMIF(G4:G20,J6,I4:I20) -> #REF!
A7: 5076 | C7: REVENDA NAC - INTERNA - NÃO CONTRIB(12%) | D7: =SUMIF(INDIRECT("TabelaSaidas[AC]"),Apuração_ICMS!A7,INDIRECT("TabelaSaidas[VC_ITEM]")) -> #REF! | E7: =SUMIF(INDIRECT("TabelaSaidas[AC]"),Apuração_ICMS!A7,INDIRECT("TabelaSaidas[BC_ICMS]")) -> #REF! | F7: =SUMIF(INDIRECT("TabelaSaidas[AC]"),Apuração_ICMS!A7,INDIRECT("TabelaSaidas[ICMS]")) -> #REF! | H7: =F7-I7 -> #REF! | I7: =E7*G7 -> #REF! | J7: 0.03 | K7: =SUMIF(G4:G20,J7,E4:E20) -> #REF! | L7: =SUMIF(G4:G20,J7,I4:I20) -> #REF!
A8: 5077 | B8: B1 | C8: REVENDA NAC - INTERNA - CONTRIB (12%) | D8: =SUMIF(INDIRECT("TabelaSaidas[AC]"),Apuração_ICMS!A8,INDIRECT("TabelaSaidas[VC_ITEM]")) -> #REF! | E8: =SUMIF(INDIRECT("TabelaSaidas[AC]"),Apuração_ICMS!A8,INDIRECT("TabelaSaidas[BC_ICMS]")) -> #REF! | F8: =SUMIF(INDIRECT("TabelaSaidas[AC]"),Apuração_ICMS!A8,INDIRECT("TabelaSaidas[ICMS]")) -> #REF! | G8: 0.03 | H8: =F8-I8 -> #REF! | I8: =E8*G8 -> #REF!
A9: 5078 | B9: B1 | C9: REVENDA NAC - INTERESTADUAL - C/ ST | D9: =SUMIF(INDIRECT("TabelaSaidas[AC]"),Apuração_ICMS!A9,INDIRECT("TabelaSaidas[VC_ITEM]")) -> #REF! | E9: =SUMIF(INDIRECT("TabelaSaidas[AC]"),Apuração_ICMS!A9,INDIRECT("TabelaSaidas[BC_ICMS]")) -> #REF! | F9: =SUMIF(INDIRECT("TabelaSaidas[AC]"),Apuração_ICMS!A9,INDIRECT("TabelaSaidas[ICMS]")) -> #REF! | G9: 0.03 | H9: =F9-I9 -> #REF! | I9: =E9*G9 -> #REF! | K9: =SUM(K6:K8) -> #REF! | L9: =SUM(L6:L8) -> #REF!
A10: 5079 | B10: B1 | C10: REVENDA NAC - INTERESTADUAL - CONTRIBUINTE | D10: =SUMIF(INDIRECT("TabelaSaidas[AC]"),Apuração_ICMS!A10,INDIRECT("TabelaSaidas[VC_ITEM]")) -> #REF! | E10: =SUMIF(INDIRECT("TabelaSaidas[AC]"),Apuração_ICMS!A10,INDIRECT("TabelaSaidas[BC_ICMS]")) -> #REF! | F10: =SUMIF(INDIRECT("TabelaSaidas[AC]"),Apuração_ICMS!A10,INDIRECT("TabelaSaidas[ICMS]")) -> #REF! | G10: 0.03 | H10: =F10-I10 -> #REF! | I10: =E10*G10 -> #REF!
A11: 5080 | B11: B1 | C11: REVENDA NAC - INTERESTADUAL - NÃO CONTRIBUINTE | D11: =SUMIF(INDIRECT("TabelaSaidas[AC]"),Apuração_ICMS!A11,INDIRECT("TabelaSaidas[VC_ITEM]")) -> #REF! | E11: =SUMIF(INDIRECT("TabelaSaidas[AC]"),Apuração_ICMS!A11,INDIRECT("TabelaSaidas[BC_ICMS]")) -> #REF! | F11: =SUMIF(INDIRECT("TabelaSaidas[AC]"),Apuração_ICMS!A11,INDIRECT("TabelaSaidas[ICMS]")) -> #REF! | G11: 0.03 | H11: =F11-I11 -> #REF! | I11: =E11*G11 -> #REF!
A12: 5081 | C12: VENDA NAC - INTERNA - NÃO CONTRIBUINTE C/ ST | D12: =SUMIF(INDIRECT("TabelaSaidas[AC]"),Apuração_ICMS!A12,INDIRECT("TabelaSaidas[VC_ITEM]")) -> #REF! | E12: =SUMIF(INDIRECT("TabelaSaidas[AC]"),Apuração_ICMS!A12,INDIRECT("TabelaSaidas[BC_ICMS]")) -> #REF! | F12: =SUMIF(INDIRECT("TabelaSaidas[AC]"),Apuração_ICMS!A12,INDIRECT("TabelaSaidas[ICMS]")) -> #REF! | H12: =F12-I12 -> #REF! | I12: =E12*G12 -> #REF! | K12: Valor Operação | L12: Transferências | M12: %
A13: 5082 | C13: VENDA NAC - INTERNA - CONTRIBUINTE C/ ST | D13: =SUMIF(INDIRECT("TabelaSaidas[AC]"),Apuração_ICMS!A13,INDIRECT("TabelaSaidas[VC_ITEM]")) -> #REF! | E13: =SUMIF(INDIRECT("TabelaSaidas[AC]"),Apuração_ICMS!A13,INDIRECT("TabelaSaidas[BC_ICMS]")) -> #REF! | F13: =SUMIF(INDIRECT("TabelaSaidas[AC]"),Apuração_ICMS!A13,INDIRECT("TabelaSaidas[ICMS]")) -> #REF! | H13: =F13-I13 -> #REF! | I13: =E13*G13 -> #REF! | K13: =D21 -> #REF! | L13: =D4 -> #REF! | M13: =L13/K13% -> #REF!
A14: 5083 | B14: B1 | C14: REVENDA NAC - INTERNA - C/ ST | D14: =SUMIF(INDIRECT("TabelaSaidas[AC]"),Apuração_ICMS!A14,INDIRECT("TabelaSaidas[VC_ITEM]")) -> #REF! | E14: =SUMIF(INDIRECT("TabelaSaidas[AC]"),Apuração_ICMS!A14,INDIRECT("TabelaSaidas[BC_ICMS]")) -> #REF! | F14: =SUMIF(INDIRECT("TabelaSaidas[AC]"),Apuração_ICMS!A14,INDIRECT("TabelaSaidas[ICMS]")) -> #REF! | G14: 0.03 | H14: =F14-I14 -> #REF! | I14: =E14*G14 -> #REF!
A21: TOTAL | D21: =SUM(D4:D20) -> #REF! | E21: =SUM(E4:E20) -> #REF! | F21: =SUM(F4:F20) -> #REF! | H21: =SUM(H4:H20) -> #REF! | I21: =SUM(I4:I20) -> #REF!
A22: OPERAÇÕES NÃO INCENTIVADAS
A23: ACUMULADOR | C23: DESCRIÇÃO | D23: VLR_OPERACAO | E23: BC ICMS | F23: Débitos ICMS | I23: ICMS NORMAL
A24: 60 | C24: COMPLEMENTAR | D24: =SUMIF(INDIRECT("TabelaSaidas[AC]"),Apuração_ICMS!A24,INDIRECT("TabelaSaidas[VC_ITEM]")) -> #REF! | E24: =SUMIF(INDIRECT("TabelaSaidas[AC]"),Apuração_ICMS!A24,INDIRECT("TabelaSaidas[BC_ICMS]")) -> #REF! | F24: =SUMIF(INDIRECT("TabelaSaidas[AC]"),Apuração_ICMS!A24,INDIRECT("TabelaSaidas[ICMS]")) -> #REF! | I24: =F24 -> #REF!
A25: 503 | C25: REVENDA DE MERCADORIAS (A PRAZO) | D25: =SUMIF(INDIRECT("TabelaSaidas[AC]"),Apuração_ICMS!A25,INDIRECT("TabelaSaidas[VC_ITEM]")) -> #REF! | E25: =SUMIF(INDIRECT("TabelaSaidas[AC]"),Apuração_ICMS!A25,INDIRECT("TabelaSaidas[BC_ICMS]")) -> #REF! | F25: =SUMIF(INDIRECT("TabelaSaidas[AC]"),Apuração_ICMS!A25,INDIRECT("TabelaSaidas[ICMS]")) -> #REF! | I25: =F25 -> #REF!
A26: 513 | C26: REVENDA CONTA E ORDEM S/ TRANS | D26: =SUMIF(INDIRECT("TabelaSaidas[AC]"),Apuração_ICMS!A26,INDIRECT("TabelaSaidas[VC_ITEM]")) -> #REF! | E26: =SUMIF(INDIRECT("TabelaSaidas[AC]"),Apuração_ICMS!A26,INDIRECT("TabelaSaidas[BC_ICMS]")) -> #REF! | F26: =SUMIF(INDIRECT("TabelaSaidas[AC]"),Apuração_ICMS!A26,INDIRECT("TabelaSaidas[ICMS]")) -> #REF! | I26: =F26 -> #REF!
A27: 583 | C27: REVENDA DE MERCADORIAS (ST) | D27: =SUMIF(INDIRECT("TabelaSaidas[AC]"),Apuração_ICMS!A27,INDIRECT("TabelaSaidas[VC_ITEM]")) -> #REF! | E27: =SUMIF(INDIRECT("TabelaSaidas[AC]"),Apuração_ICMS!A27,INDIRECT("TabelaSaidas[BC_ICMS]")) -> #REF! | F27: =SUMIF(INDIRECT("TabelaSaidas[AC]"),Apuração_ICMS!A27,INDIRECT("TabelaSaidas[ICMS]")) -> #REF! | I27: =F27 -> #REF!
A28: 610 | C28: REVENDA ZFM / ALC (A PRAZO) | D28: =SUMIF(INDIRECT("TabelaSaidas[AC]"),Apuração_ICMS!A28,INDIRECT("TabelaSaidas[VC_ITEM]")) -> #REF! | E28: =SUMIF(INDIRECT("TabelaSaidas[AC]"),Apuração_ICMS!A28,INDIRECT("TabelaSaidas[BC_ICMS]")) -> #REF! | F28: =SUMIF(INDIRECT("TabelaSaidas[AC]"),Apuração_ICMS!A28,INDIRECT("TabelaSaidas[ICMS]")) -> #REF! | I28: =F28 -> #REF!
A29: 854 | C29: TRANSFERÊNCIA DE MERCADORIA | D29: =SUMIF(INDIRECT("TabelaSaidas[AC]"),Apuração_ICMS!A29,INDIRECT("TabelaSaidas[VC_ITEM]")) -> #REF! | E29: =SUMIF(INDIRECT("TabelaSaidas[AC]"),Apuração_ICMS!A29,INDIRECT("TabelaSaidas[BC_ICMS]")) -> #REF! | F29: =SUMIF(INDIRECT("TabelaSaidas[AC]"),Apuração_ICMS!A29,INDIRECT("TabelaSaidas[ICMS]")) -> #REF! | I29: =F29 -> #REF!
A30: 910 | C30: SAIDA DE BRINDE | D30: =SUMIF(INDIRECT("TabelaSaidas[AC]"),Apuração_ICMS!A30,INDIRECT("TabelaSaidas[VC_ITEM]")) -> #REF! | E30: =SUMIF(INDIRECT("TabelaSaidas[AC]"),Apuração_ICMS!A30,INDIRECT("TabelaSaidas[BC_ICMS]")) -> #REF! | F30: =SUMIF(INDIRECT("TabelaSaidas[AC]"),Apuração_ICMS!A30,INDIRECT("TabelaSaidas[ICMS]")) -> #REF! | I30: =F30 -> #REF!
A31: 911 | C31: AMOSTRA GRATIS | D31: =SUMIF(INDIRECT("TabelaSaidas[AC]"),Apuração_ICMS!A31,INDIRECT("TabelaSaidas[VC_ITEM]")) -> #REF! | E31: =SUMIF(INDIRECT("TabelaSaidas[AC]"),Apuração_ICMS!A31,INDIRECT("TabelaSaidas[BC_ICMS]")) -> #REF! | F31: =SUMIF(INDIRECT("TabelaSaidas[AC]"),Apuração_ICMS!A31,INDIRECT("TabelaSaidas[ICMS]")) -> #REF! | I31: =F31 -> #REF!
A32: 916 | C32: RETORNO CONSERTO | D32: =SUMIF(INDIRECT("TabelaSaidas[AC]"),Apuração_ICMS!A32,INDIRECT("TabelaSaidas[VC_ITEM]")) -> #REF! | E32: =SUMIF(INDIRECT("TabelaSaidas[AC]"),Apuração_ICMS!A32,INDIRECT("TabelaSaidas[BC_ICMS]")) -> #REF! | F32: =SUMIF(INDIRECT("TabelaSaidas[AC]"),Apuração_ICMS!A32,INDIRECT("TabelaSaidas[ICMS]")) -> #REF! | I32: =F32 -> #REF!
A33: 920 | C33: SAIDA EM REMESSA VASILHAME | D33: =SUMIF(INDIRECT("TabelaSaidas[AC]"),Apuração_ICMS!A33,INDIRECT("TabelaSaidas[VC_ITEM]")) -> #REF! | E33: =SUMIF(INDIRECT("TabelaSaidas[AC]"),Apuração_ICMS!A33,INDIRECT("TabelaSaidas[BC_ICMS]")) -> #REF! | F33: =SUMIF(INDIRECT("TabelaSaidas[AC]"),Apuração_ICMS!A33,INDIRECT("TabelaSaidas[ICMS]")) -> #REF! | I33: =F33 -> #REF!
A34: 5090 | C34: VENDA PARA ZONA FRANCA CAMEX | D34: =SUMIF(INDIRECT("TabelaSaidas[AC]"),Apuração_ICMS!A34,INDIRECT("TabelaSaidas[VC_ITEM]")) -> #REF! | E34: =SUMIF(INDIRECT("TabelaSaidas[AC]"),Apuração_ICMS!A34,INDIRECT("TabelaSaidas[BC_ICMS]")) -> #REF! | F34: =SUMIF(INDIRECT("TabelaSaidas[AC]"),Apuração_ICMS!A34,INDIRECT("TabelaSaidas[ICMS]")) -> #REF! | I34: =F34 -> #REF!
A35: 5094 | C35: REV NACIONAL INTERNA ZONA FRANCA | D35: =SUMIF(INDIRECT("TabelaSaidas[AC]"),Apuração_ICMS!A35,INDIRECT("TabelaSaidas[VC_ITEM]")) -> #REF! | E35: =SUMIF(INDIRECT("TabelaSaidas[AC]"),Apuração_ICMS!A35,INDIRECT("TabelaSaidas[BC_ICMS]")) -> #REF! | F35: =SUMIF(INDIRECT("TabelaSaidas[AC]"),Apuração_ICMS!A35,INDIRECT("TabelaSaidas[ICMS]")) -> #REF! | I35: =F35 -> #REF!
A36: 5095 | C36: REMESSA PARA INDUSTRIALIZAÇÃO FORA RET | D36: =SUMIF(INDIRECT("TabelaSaidas[AC]"),Apuração_ICMS!A36,INDIRECT("TabelaSaidas[VC_ITEM]")) -> #REF! | E36: =SUMIF(INDIRECT("TabelaSaidas[AC]"),Apuração_ICMS!A36,INDIRECT("TabelaSaidas[BC_ICMS]")) -> #REF! | F36: =SUMIF(INDIRECT("TabelaSaidas[AC]"),Apuração_ICMS!A36,INDIRECT("TabelaSaidas[ICMS]")) -> #REF! | I36: =F36 -> #REF!
A37: TOTAL | D37: =SUM(D24:D36) -> #REF! | E37: =SUM(E24:E36) -> #REF! | F37: =SUM(F24:F36) -> #REF! | I37: =SUM(I24:I36) -> #REF!
A39: APURAÇÃO NORMAL
A40: (1) TOTAL DE DÉBITOS NA APURAÇÃO NORMAL | E40: =SUM(INDIRECT("TabelaSaidas[ICMS]")) -> #REF!
A41: (2) OUTROS DÉBITOS | E41: 0
A42: (3) ESTORNO DE DÉBITOS REL. OP. INCENTIVADAS | E42: =F21*-1 -> #REF!
A43: (4) ESTORNO DE DÉBITOS - OUTRAS SITUAÇÕES | E43: 0
A44: (5) CRÉDITOS APROPRIADOS NA ESCRITURAÇÃO | E44: {=INDIRECT("TabelaEntradas[[#Totais];[VLR-ICMS]]")*-1} -> #REF!
A45: (6) SALDO CREDOR ANTERIOR | E45: 0
A46: (7) OUTROS CRÉDITOS (NÃO APROP. PERIODOS ANT) | E46: 0
A47: (8) ESTORNO DE CREDITO OP INCENTIVADAS | E47: {=INDIRECT("TabelaEntradas[[#Totais];[Estorno]]")} -> #REF!
...
